2018-06-13 18:57:41,439 ERROR: Exception on /user/1 [GET] [in c:\users\jacob\appdata\local\programs\python\python36\lib\site-packages\flask\app.py:1761]
Traceback (most recent call last):
  File "c:\users\jacob\appdata\local\programs\python\python36\lib\site-packages\flask\app.py", line 2292, in wsgi_app
    response = self.full_dispatch_request()
  File "c:\users\jacob\appdata\local\programs\python\python36\lib\site-packages\flask\app.py", line 1815, in full_dispatch_request
    rv = self.handle_user_exception(e)
  File "c:\users\jacob\appdata\local\programs\python\python36\lib\site-packages\flask\app.py", line 1718, in handle_user_exception
    reraise(exc_type, exc_value, tb)
  File "c:\users\jacob\appdata\local\programs\python\python36\lib\site-packages\flask\_compat.py", line 35, in reraise
    raise value
  File "c:\users\jacob\appdata\local\programs\python\python36\lib\site-packages\flask\app.py", line 1813, in full_dispatch_request
    rv = self.dispatch_request()
  File "c:\users\jacob\appdata\local\programs\python\python36\lib\site-packages\flask\app.py", line 1799, in dispatch_request
    return self.view_functions[rule.endpoint](**req.view_args)
  File "c:\users\jacob\appdata\local\programs\python\python36\lib\site-packages\flask_login\utils.py", line 261, in decorated_view
    return func(*args, **kwargs)
  File "C:\Users\jacob\Projects\Wanderlist\app\main\routes.py", line 57, in user
    explored=explored, favorites=favorites, locations=locations)
  File "c:\users\jacob\appdata\local\programs\python\python36\lib\site-packages\flask\templating.py", line 135, in render_template
    context, ctx.app)
  File "c:\users\jacob\appdata\local\programs\python\python36\lib\site-packages\flask\templating.py", line 117, in _render
    rv = template.render(context)
  File "c:\users\jacob\appdata\local\programs\python\python36\lib\site-packages\jinja2\asyncsupport.py", line 76, in render
    return original_render(self, *args, **kwargs)
  File "c:\users\jacob\appdata\local\programs\python\python36\lib\site-packages\jinja2\environment.py", line 1008, in render
    return self.environment.handle_exception(exc_info, True)
  File "c:\users\jacob\appdata\local\programs\python\python36\lib\site-packages\jinja2\environment.py", line 780, in handle_exception
    reraise(exc_type, exc_value, tb)
  File "c:\users\jacob\appdata\local\programs\python\python36\lib\site-packages\jinja2\_compat.py", line 37, in reraise
    raise value.with_traceback(tb)
  File "C:\Users\jacob\Projects\Wanderlist\app\templates\main\user.html", line 6, in top-level template code
    {% set active_page = "profile" %}
  File "C:\Users\jacob\Projects\Wanderlist\app\templates\layout.html", line 23, in top-level template code
    {% block body %}{% endblock %}
  File "C:\Users\jacob\Projects\Wanderlist\app\templates\main\user.html", line 66, in block "body"
    <a class="text-teal" href="{{url_for ('auth.logout') }}">Logout</a>
  File "c:\users\jacob\appdata\local\programs\python\python36\lib\site-packages\flask\helpers.py", line 356, in url_for
    return appctx.app.handle_url_build_error(error, endpoint, values)
  File "c:\users\jacob\appdata\local\programs\python\python36\lib\site-packages\flask\app.py", line 2061, in handle_url_build_error
    reraise(exc_type, exc_value, tb)
  File "c:\users\jacob\appdata\local\programs\python\python36\lib\site-packages\flask\_compat.py", line 35, in reraise
    raise value
  File "c:\users\jacob\appdata\local\programs\python\python36\lib\site-packages\flask\helpers.py", line 345, in url_for
    force_external=external)
  File "c:\users\jacob\appdata\local\programs\python\python36\lib\site-packages\werkzeug\routing.py", line 1776, in build
    raise BuildError(endpoint, values, method, self)
werkzeug.routing.BuildError: Could not build url for endpoint 'logout'. Did you mean 'auth.logout' instead?
2018-06-13 21:07:32,403 INFO: Wanderlist startup [in C:\Users\jacob\Projects\Wanderlist\app\__init__.py:46]
